<?xml version="1.0"?>
<robot name="tortoisebot">

  <link name="base_link">
    <visual>
      <geometry>
        <box size="0.432 0.231 0.0925"/>
      </geometry>
      <material name="silver">
        <color rgba="0.75 0.75 0.75 1"/>
      </material>
    </visual>
    <collision>
      <geometry>
        <box size="0.432 0.231 0.0925"/>
      </geometry>
    </collision>
    <inertial>
      <mass value="9"/>
      <inertia ixx="0.015" iyy="0.0375" izz="0.0375" ixy="0" ixz="0" iyz="0"/>
    </inertial>
  </link>

  <link name="lift">
    <visual>
      <geometry>
        <box size="0.05 0.05 1.7"/>
      </geometry>
      <material name="silver"/>
    </visual>
    <collision>
      <geometry>
        <box size="0.05 0.05 1.7"/>
      </geometry>
    </collision>
    <inertial>
      <mass value="6"/>
      <inertia ixx="0.00083" iyy="0.00083" izz="0.000167" ixy="0" ixz="0" iyz="0"/>
    </inertial>
  </link>

  <joint name="lift_joint" type="fixed">
    <axis xyz="0 0 1"/>
    <parent link="base_link"/>
    <child link="lift"/>
    <origin rpy="0 0 0" xyz="0 0 0.89"/>
  </joint>

  <link name="back_right_wheel">
    <visual>
      <geometry>
        <cylinder length="0.05" radius="0.0508"/>
      </geometry>
      <material name="black">
        <color rgba="0 0 0 1"/>
      </material>
    </visual>
    <collision>
      <geometry>
        <cylinder length="0.05" radius="0.0508"/>
      </geometry>
    </collision>
    <inertial>
      <mass value="0.05"/>
      <inertia ixx="5.1458e-5" iyy="5.1458e-5" izz="6.125e-5" ixy="0" ixz="0" iyz="0"/>
    </inertial>
  </link>

  <joint name="back_right_wheel_joint" type="continuous">
    <axis xyz="0 0 1"/>
    <parent link="base_link"/>
    <child link="back_right_wheel"/>
    <origin rpy="-1.5708 0 0" xyz="-0.1742 -0.142 -.0178"/>
  </joint>

  <link name="front_right_wheel">
    <visual>
      <geometry>
        <cylinder length="0.05" radius="0.0508"/>
      </geometry>
      <material name="black">
        <color rgba="0 0 0 1"/>
      </material>
    </visual>
    <collision>
      <geometry>
        <cylinder length="0.05" radius="0.0508"/>
      </geometry>
    </collision>
    <inertial>
      <mass value="0.05"/>
      <inertia ixx="5.1458e-5" iyy="5.1458e-5" izz="6.125e-5" ixy="0" ixz="0" iyz="0"/>
    </inertial>
  </link>

  <joint name="front_right_wheel_joint" type="continuous">
    <axis xyz="0 0 1"/>
    <parent link="base_link"/>
    <child link="front_right_wheel"/>
    <origin rpy="-1.5708 0 0" xyz="0.1742 -0.142 -.0178"/>
  </joint>

  <link name="back_left_wheel">
    <visual>
      <geometry>
        <cylinder length="0.05" radius="0.0508"/>
      </geometry>
      <material name="black"/>
    </visual>
    <collision>
      <geometry>
        <cylinder length="0.05" radius="0.0508"/>
      </geometry>
    </collision>
    <inertial>
      <mass value="0.05"/>
      <inertia ixx="5.1458e-5" iyy="5.1458e-5" izz="6.125e-5" ixy="0" ixz="0" iyz="0"/>
    </inertial>
  </link>

  <joint name="back_left_wheel_joint" type="continuous">
    <axis xyz="0 0 1"/>
    <parent link="base_link"/>
    <child link="back_left_wheel"/>
    <origin rpy="-1.5708 0 0" xyz="-0.1742 0.142 -.0178"/>
  </joint>



<link name="front_left_wheel">
    <visual>
      <geometry>
        <cylinder length="0.05" radius="0.0508"/>
      </geometry>
      <material name="black"/>
    </visual>
    <collision>
      <geometry>
        <cylinder length="0.05" radius="0.0508"/>
      </geometry>
    </collision>
    <inertial>
      <mass value="0.05"/>
      <inertia ixx="5.1458e-5" iyy="5.1458e-5" izz="6.125e-5" ixy="0" ixz="0" iyz="0"/>
    </inertial>
  </link>

  <joint name="front_left_wheel_joint" type="continuous">
    <axis xyz="0 0 1"/>
    <parent link="base_link"/>
    <child link="front_left_wheel"/>
    <origin rpy="-1.5708 0 0" xyz="0.1742 0.142 -.0178"/>
  </joint>

  <gazebo>
    <plugin name="differential_drive_controller" filename="libgazebo_ros_diff_drive.so">
      <leftJoint>left_wheel_joint</leftJoint>
      <rightJoint>right_wheel_joint</rightJoint>
      <robotBaseFrame>base_link</robotBaseFrame>
      <wheelSeparation>0.25</wheelSeparation>
      <wheelDiameter>0.07</wheelDiameter>
      <publishWheelJointState>true</publishWheelJointState>
    </plugin>
  </gazebo>
</robot>
